Workbook

Sheet IS_Rules
A1: Rule Name | B1: Rule Desciption | C1: Rule Dimanesion | D1: Rule Expression
A2: ZB_G13_MATNR_TargetQMSystemReference | B2: Rule to check if Target QM System value for Material master data is valid according to the available values in the appropriate reference table in a standard SAP ECC 6.0 system. | C2: Consistency | D2: BEGIN RETURN exists('SAP', 'TQ02', 'QSSYS', $P_I_TargetQMSystem); END
A3: ZB_G13_MATNR_FairShareRuleDomainReference | B3: Rule to check if Fair Share Rule value for a Material master is valid according to the appropriate reference domain or value range for a standard SAP ECC 6.0 system. | C3: Consistency | D3: BEGIN RETURN $P_I_FairShare_Rule IS NULL OR length($P_I_FairShare_Rule) = 0 OR $P_I_FairShare_Rule IN ('A', 'B', 'X'); END
A4: ZB_G13_MATNR_TaskListTypeReference | B4: Rule to check if Task List Type value for Material master data is valid according to the available values in the appropriate reference table in a standard SAP ECC 6.0 system. | C4: Consistency | D4: BEGIN RETURN exists('SAP', 'H_TCA01', 'PLNTY', $P_I_TaskListType); END
A5: ZB_G14_CUST_TradingPartnerReference | B5: Rule to check if Trading Partner value for Business Partner / Customer / Vendor master data is valid according to the available values in the appropriate reference table in a standard SAP ECC 6.0 system. | C5: Consistency | D5: BEGIN RETURN exists('SAP', 'T880', 'RCOMP', $P_I_TradingPartner); END
A6: ZB_G14_CUST_SalesCurrencyExists | B6: Rule to validate if Customer Sales Currency is set | C6: Completeness | D6: BEGIN RETURN $P_I_Currency IS NOT NULL AND $P_I_Currency != ''; END
A7: ZB_G15_VNDR_LicensevalidToDateExists | B7: Rule to check if the License valid to date for Business Partner / Customer / Vendor exists | C7: Completeness | D7: BEGIN RETURN $P_I_LicenseValidToDate IS NOT NULL AND $P_I_LicenseValidToDate != to_date('', 'yyyy.mm.dd'); END
A8: ZB_G13_MATNR_AvailabilityCheckExists | B8: Rule to check for existence of Availability check in Material master data for a standard SAP ECC 6.0 system | C8: Completeness | D8: BEGIN RETURN $P_I_AvailabilityCheck IS NOT NULL AND $P_I_AvailabilityCheck != ''; END
A9: ZB_G14_CUST_CompanyCodeExists | B9: Rule to check if Company code exists for Business Partner / Customer / Vendor master data for a standard SAP ECC 6.0 system | C9: Completeness | D9: BEGIN RETURN $P_I_CompanyCode IS NOT NULL AND $P_I_CompanyCode != ''; END
A10: ZB_G15_VNDR_StatisticeGroupReference | B10: Rule to check if Statistics Group value for Business Partner / Customer / Vendor master data is valid according to the available values in the appropriate reference table in a standard SAP ECC 6.0 system. | C10: Consistency | D10: BEGIN RETURN exists('SAP', 'TVSD', 'STGKU', $P_I_StatisticsGroup); END
A11: ZB_G15_VNDR_TaxNumberReference | B11: Rule to check if Tax Number value for Vendor master data is valid according to the available values in the appropriate reference table in a standard SAP ECC 6.0 system. | C11: Consistency | D11: BEGIN RETURN exists('SAP', 'M_KREDA', 'LIFNR', $P_I_TaxNumber); END
A12: ZB_G13_MATNR_MRPTypeReference | B12: Rule to check if MRP Type value for Material master data is valid according to the available values in the appropriate reference table in a standard SAP ECC 6.0 system. | C12: Consistency | D12: BEGIN RETURN exists('SAP', 'T438A', 'DISMM', $P_I_MRPType); END
... A169: ZB_G13_MATNR_PlanningCycleReference | B169: Rule to check if Planning Cycle value for Material master data is valid according to the available values in the appropriate reference table in a standard SAP ECC 6.0 system. | C169: Consistency | D169: BEGIN RETURN exists('SAP', 'MARC', 'MRPPP', $P_I_PlanningCycle); END
A170: ZB_G13_MATNR_TaxIndicatorforMaterialReference | C170: Consistency | D170: BEGIN RETURN exists('SAP', 'TMKM1', 'TAXIM', $P_I_TaxIndicator); END
A171: ZB_G14_CUST_PostalCodeAndCityExists | B171: Rule to check if Postal Code and City exist for Business Partner (Customer / Vendor) Master data in a standard SAP ECC 6.0 system | C171: Completeness | D171: BEGIN RETURN $P_I_PostalCodeCity IS NOT NULL AND $P_I_PostalCodeCity != ''; END
A172: ZB_G14_CUST_PlanningGroupExists | B172: Rule to validate if Customer Planning group exists. | C172: Completeness | D172: BEGIN RETURN $P_I_PlanningGroup IS NOT NULL AND $P_I_PlanningGroup != ''; END
A173: ZB_G13_MATNR_ProductAllocationReference | B173: Rule to check if Product Allocation value for Material master data is valid according to the available values in the appropriate reference table in a standard SAP ECC 6.0 system. | C173: Consistency | D173: BEGIN RETURN exists('SAP', 'T190S', 'KOSCH', $P_I_ProductAllocation); END
A174: ZB_G14_CUST_DistributionChannelExists | B174: Rule to check if Distribution Channel exists for Customer master data for a standard SAP ECC 6.0 system | C174: Completeness | D174: BEGIN RETURN $P_I_DistributionChannel IS NOT NULL AND $P_I_DistributionChannel != ''; END
A175: ZB_G14_CUST_LicenseValidFromDateExists | B175: Rule to check if License Valid from date exists for Business Partner / Customer / Vendor exists | C175: Completeness | D175: BEGIN RETURN $P_I_LicenseValidFromDate IS NOT NULL AND $P_I_LicenseValidFromDate != to_date('', 'yyyy.mm.dd'); END
A176: ZB_G14_CUST_CustomerAccountGroupReference | B176: Rule to check if Account group value for Customer master data is valid according to the available values in the appropriate reference table in a standard SAP ECC 6.0 system. | C176: Consistency | D176: BEGIN RETURN exists('SAP', 'T077D', 'KTOKD', $P_I_AccountGroup); END
A177: ZB_G14_CUST_TransportationZoneExists | B177: ule to check if Transportation zone exists for Customer master data for a standard SAP ECC 6.0 system | C177: Completeness | D177: BEGIN RETURN $P_I_TransportationZone IS NOT NULL AND $P_I_TransportationZone != ''; END
A178: ZB_G14_CUST_AccountAssignmentGroupReference | B178: Rule to check if Account Assignment Group value for Customer master data is valid according to the available values in the appropriate reference table in a standard SAP ECC 6.0 system. | C178: Consistency | D178: BEGIN RETURN exists('SAP', 'TVKT', 'KTGRD', $P_I_AccountAssignmentGroup); END
A179: ZB_G13_MATNR_MaterialGroupReference | B179: Rule to check if Material Group value for Material master data is valid according to the available values in the appropriate reference table in a standard SAP ECC 6.0 system. | C179: Consistency | D179: BEGIN RETURN exists('SAP', 'T023', 'MATKL', $P_I_MaterialGroup); END
A180: ZB_G13_MATNR_QuotaArrangementUsageReference | B180: Rule to check if Quota Arrangement Usage value for Material master data is valid according to the available values in the appropriate reference table in a standard SAP ECC 6.0 system. | C180: Consistency | D180: BEGIN RETURN exists('SAP', 'TMQ2', 'USEQU', $P_I_QuotaArrangementUsage); END
A181: ZB_G13_MATNR_PurchasingValueKeyReference | B181: Rule to check if Purchasing Value Key value for Material master data is valid according to the available values in the appropriate reference table in a standard SAP ECC 6.0 system. | C181: Consistency | D181: BEGIN RETURN exists('SAP', 'T405', 'EKWSL', $P_I_PurchasingValueKey); END
A182: ZB_G14_CUST_ReconciliationAccountReference | B182: Rule to check if Reconciliation Account value for Business Partner / Customer / Vendor master data is valid according to the available values in the appropriate reference table in a standard SAP ECC 6.0 system. | C182: Consistency | D182: BEGIN RETURN exists('SAP', 'SKB1', 'SAKNR', $P_I_ReconciliationAccount); END
... A194: ZB_G15_VNDR_BankCountryKeyExists | B194: Rule to check if Bank country key exists for Business Partner / Customer / Vendor master data for a standard SAP ECC 6.0 system | C194: Completeness | D194: BEGIN RETURN $P_I_BankCountryKey IS NOT NULL AND $P_I_BankCountryKey != ''; END
A195: ZB_G15_VNDR_TitleDomainReference | C195: Consistency | D195: BEGIN RETURN exists('SAP', 'TSAD3T', 'TITLE_MEDI', $P_I_Title) OR $P_I_Title IS NULL OR $P_I_Title=''; END
A196: ZB_G15_VNDR_AccountGroupExists | B196: Rule to validate if Business Partner / Customer / Vendor Account group exists. | C196: Completeness | D196: BEGIN RETURN $P_I_AccountGroup IS NOT NULL AND $P_I_AccountGroup != ''; END
A197: ZB_G13_MATNR_BulkStorageRefeference | B197: Rule to check if Bulk Storage value for Material master data is valid according to the available values in the appropriate reference table in a standard SAP ECC 6.0 system. | C197: Consistency | D197: BEGIN RETURN exists('SAP', 'T338', 'BLOCK', $P_I_BulkStorage); END
A198: ZB_G14_CUST_DunningRecipientReference | B198: Rule to check if Dunning Recipient value for Business Partner / Customer / Vendor master data is valid according to the available values in the appropriate reference table in a standard SAP ECC 6.0 system. | C198: Consistency | D198: BEGIN RETURN exists('SAP', 'M_DEBID', 'KUNNR', $P_I_DunningRecipient); END
A199: ZB_G15_VNDR_ServiceAgentProcedureGroupReference | B199: Rule to check if Service Agent Procedure Group value for Vendor master data is valid according to the available values in the appropriate reference table in a standard SAP ECC 6.0 system. | C199: Consistency | D199: BEGIN RETURN exists('SAP', 'TVFCD', 'DLGRP', $P_I_ServiceAgentProcGroup); END
A200: ZB_G13_MATNR_DescriptionExists | B200: Rule to check for existence of Material Description in Material master data for a standard SAP ECC 6.0 system | C200: Completeness | D200: BEGIN RETURN $P_I_Description IS NOT NULL AND $P_I_Description != ''; END
A201: ZB_G14_CUST_VATRegistrationNumberExists | B201: Rule to validate if Business Partner / Customer / Vendor VAT Registration Number exists. It is specific to EU countries mostly | C201: Completeness | D201: BEGIN RETURN $P_I_VATRegNumber IS NOT NULL AND $P_I_VATRegNumber != ''; END
A202: ZB_G15_VNDR_FIYearVariantReference | B202: Rule to check if Fiscal Year Variant value for Business Partner / Customer / Vendor master data is valid according to the available values in the appropriate reference table in a standard SAP ECC 6.0 system. | C202: Consistency | D202: BEGIN RETURN exists('SAP', 'T009', 'PERIV', $P_I_FIYearVariant); END
A203: ZB_G15_VNDR_PODRelevantDomainReference | B203: Rule to check if POD Relevant value for a Business Partner / Customer / Vendor is valid according to the appropriate reference domain or value range for a standard SAP ECC 6.0 system. | C203: Consistency | D203: BEGIN RETURN $P_I_PODRelevant IS NULL OR length($P_I_PODRelevant) = 0 OR $P_I_PODRelevant IN ('A', 'B'); END
A204: ZB_G14_CUST_ReconAccountExists | B204: Rule to check if Reconciliation Account exists for Business Partner / Customer / Vendor master data for a standard SAP ECC 6.0 system | C204: Completeness | D204: BEGIN RETURN $P_I_ReconAccount IS NOT NULL AND $P_I_ReconAccount != ''; END
A205: ZB_G15_VNDR_TermsOfPaymentReference | B205: Rule to check if Terms of Payment key value for Business Partner / Customer / Vendor master data is valid according to the available values in the appropriate reference table in a standard SAP ECC 6.0 system. | C205: Consistency | D205: BEGIN RETURN exists('SAP', 'T052', 'ZTERM', $P_I_TermsOfPayment); END
A206: ZB_G13_MATNR_DeliveringPlantReference | B206: Rule to check if Delivering Plant value for Material master data is valid according to the available values in the appropriate reference table in a standard SAP ECC 6.0 system. | C206: Consistency | D206: BEGIN RETURN exists('SAP', 'T001W', 'WERKS', $P_I_DeliveringPlant); END
A207: ZB_G14_CUST_SortFieldExists | B207: Rule to validate if Sort Field for a Business Partner / Customer / Vendor exists. | C207: Completeness | D207: BEGIN RETURN $P_I_SortField IS NOT NULL AND $P_I_SortField != ''; END
...

Sheet IS_Binding_Rule_to_Views
A1: Rule Name | B1: Attribute | C1: Attribute Parameter (IS Internal) | D1: View Name (IS Internal) | E1: Notes
A2: ZB_G14_CUST_AccountingClerkReference | B2: Acctg clerk | C2: $P_I_AccountingClerk | D2: ZB_G14_CUST_CompanyCodeData_Correspondence
A3: ZB_G14_CUST_BankStatementIndicatorReference | B3: Bank statement | C3: $P_I_BankStmtInd | D3: ZB_G14_CUST_CompanyCodeData_Correspondence
A4: ZB_G14_CUST_DunningBlockReference | B4: Dunning block | C4: $P_I_DunningBlock | D4: ZB_G14_CUST_CompanyCodeData_Correspondence
A5: ZB_G14_CUST_DunningClerkReference | B5: Dunning clerk | C5: $P_I_DunningClerk | D5: ZB_G14_CUST_CompanyCodeData_Correspondence
A6: ZB_G14_CUST_DunningNoticeGroupingKeyReference | B6: Grouping key | C6: $P_I_DunningNoticeGroupingkey | D6: ZB_G14_CUST_CompanyCodeData_Correspondence
A7: ZB_G14_CUST_DunningProcedureReference | B7: Dunn Procedure | C7: $P_I_DunningProcedure | D7: ZB_G14_CUST_CompanyCodeData_Correspondence
A8: ZB_G14_CUST_DunningRecipientReference | B8: Dunn Recipient | C8: $P_I_DunningRecipient | D8: ZB_G14_CUST_CompanyCodeData_Correspondence
A9: ZB_G14_CUST_TermsOfPaymentExists | B9: Terms of payment | C9: $P_I_TermsOfPayment | D9: ZB_G14_CUST_CompanyCodeData_PaymentTransactions
A10: ZB_G14_CUST_CompanyCodeExists | B10: Company Code | C10: $P_I_CompanyCode | D10: ZB_G14_CUST_CompanyCodeData_PaymentTransactions
A11: ZB_G14_CUST_BillOfExchangePaymentTermReference | B11: B e charges payt term | C11: $P_I_BePaymentTerm | D11: ZB_G14_CUST_CompanyCodeData_PaymentTransactions
A12: ZB_G14_CUST_CustomerCompanyCodeReference | B12: Company Code | C12: $P_I_CompanyCode | D12: ZB_G14_CUST_CompanyCodeData_PaymentTransactions
A13: ZB_G14_CUST_GroupingKeyReference | B13: Grouping key | C13: $P_I_GroupingKey | D13: ZB_G14_CUST_CompanyCodeData_PaymentTransactions
... A324: ZB_G14_CUST_USPostalCodeFormat | B324: Country | C324: $P_I_Country | D324: ZB_G14_CUST_GeneralData_Address

Sheet IS_Views
A1: View Name (IS Internal) | B1: View Description | C1: Nullable Attribute | D1: Attribute Description | E1: SAP Table.AttributeName | F1: Attribute Name | G1: Attribute Description2 | H1: Data Type | I1: Length | J1: Precision | K1: Scale | L1: Connection Name | M1: Table Name | N1: Join Type | O1: Join Expression | P1: Filter expression
A2: ZB_G13_MATNR_Accounting1 | B2: Material Accounting data view 1 for a standard SAP ECC 6.0 system | C2: FALSE | D2: Material | E2: SAP.MARA.MATNR | F2: MATNR | H2: varchar | I2: 18 | P2: SAP.MAKT.SPRAS = 'E'
A3: ZB_G13_MATNR_Accounting1 | B3: Material Accounting data view 1 for a standard SAP ECC 6.0 system | C3: TRUE | D3: Description | E3: SAP.MAKT.MAKTX | F3: MAKTX | H3: varchar | I3: 40 | P3: SAP.MAKT.SPRAS = 'E'
A4: ZB_G13_MATNR_Accounting1 | B4: Material Accounting data view 1 for a standard SAP ECC 6.0 system | C4: TRUE | D4: Material Type | E4: SAP.MARA.MTART | F4: MTART | G4: Material Type | H4: varchar | I4: 4 | P4: SAP.MAKT.SPRAS = 'E'
A5: ZB_G13_MATNR_Accounting1 | B5: Material Accounting data view 1 for a standard SAP ECC 6.0 system | C5: FALSE | D5: Plant | E5: SAP.MARC.WERKS | F5: WERKS | H5: varchar | I5: 4 | P5: SAP.MAKT.SPRAS = 'E'
A6: ZB_G13_MATNR_Accounting1 | B6: Material Accounting data view 1 for a standard SAP ECC 6.0 system | C6: TRUE | D6: Base Unit of Measure | E6: SAP.MARA.MEINS | F6: MEINS | H6: varchar | I6: 3 | P6: SAP.MAKT.SPRAS = 'E'
A7: ZB_G13_MATNR_Accounting1 | B7: Material Accounting data view 1 for a standard SAP ECC 6.0 system | C7: TRUE | D7: Valuation Category | E7: SAP.MARC.BWTTY | F7: BWTTY | H7: varchar | I7: 1 | P7: SAP.MAKT.SPRAS = 'E'
A8: ZB_G13_MATNR_Accounting1 | B8: Material Accounting data view 1 for a standard SAP ECC 6.0 system | C8: TRUE | D8: Division | E8: SAP.MARA.SPART | F8: SPART | H8: varchar | I8: 2 | P8: SAP.MAKT.SPRAS = 'E'
A9: ZB_G13_MATNR_Accounting1 | B9: Material Accounting data view 1 for a standard SAP ECC 6.0 system | C9: TRUE | D9: Price determ | E9: SAP.MBEW.MLAST | F9: MLAST | G9: Material Price Determination: Control | H9: varchar | I9: 1 | P9: SAP.MAKT.SPRAS = 'E'
A10: ZB_G13_MATNR_Accounting1 | B10: Material Accounting data view 1 for a standard SAP ECC 6.0 system | C10: TRUE | D10: ML act | E10: SAP.MBEW.MLMAA | F10: MLMAA | G10: Material ledger activated at material level | H10: varchar | I10: 1 | P10: SAP.MAKT.SPRAS = 'E'
A11: ZB_G13_MATNR_Accounting1 | B11: Material Accounting data view 1 for a standard SAP ECC 6.0 system | C11: TRUE | D11: Valuation Class | E11: SAP.MBEW.BKLAS | F11: BKLAS | G11: Valuation Class | H11: varchar | I11: 4 | P11: SAP.MAKT.SPRAS = 'E'
A12: ZB_G13_MATNR_Accounting1 | B12: Material Accounting data view 1 for a standard SAP ECC 6.0 system | C12: TRUE | D12: VC Sales order stk | E12: SAP.MBEW.EKLAS | F12: EKLAS | G12: Valuation Class for Sales Order Stock | H12: varchar | I12: 4 | P12: SAP.MAKT.SPRAS = 'E'
A13: ZB_G13_MATNR_Accounting1 | B13: Material Accounting data view 1 for a standard SAP ECC 6.0 system | C13: TRUE | D13: Proj stk val class | E13: SAP.MBEW.QKLAS | F13: QKLAS | G13: Valuation Class for Project Stock | H13: varchar | I13: 4 | P13: SAP.MAKT.SPRAS = 'E'
A14: ZB_G13_MATNR_Accounting1 | B14: Material Accounting data view 1 for a standard SAP ECC 6.0 system | C14: TRUE | D14: Price control | E14: SAP.MBEW.VPRSV | F14: VPRSV | G14: Price control indicator | H14: varchar | I14: 1 | P14: SAP.MAKT.SPRAS = 'E'
A15: ZB_G13_MATNR_Accounting1 | B15: Material Accounting data view 1 for a standard SAP ECC 6.0 system | C15: TRUE | D15: Price unit | E15: SAP.MBEW.PEINH | F15: PEINH | G15: Price Unit | H15: decimal | J15: 5 | K15: 0 | P15: SAP.MAKT.SPRAS = 'E'
A16: ZB_G13_MATNR_Accounting1 | B16: Material Accounting data view 1 for a standard SAP ECC 6.0 system | C16: TRUE | D16: Moving price | E16: SAP.MBEW.VERPR | F16: VERPR | G16: Moving Average Price/Periodic Unit Price | H16: decimal | J16: 11 | K16: 2 | P16: SAP.MAKT.SPRAS = 'E'
A17: ZB_G13_MATNR_Accounting1 | B17: Material Accounting data view 1 for a standard SAP ECC 6.0 system | C17: TRUE | D17: Standard price | E17: SAP.MBEW.STPRS | F17: STPRS | G17: Standard price | H17: decimal | J17: 11 | K17: 2 | P17: SAP.MAKT.SPRAS = 'E'
A18: ZB_G13_MATNR_Accounting1 | B18: Material Accounting data view 1 for a standard SAP ECC 6.0 system | C18: TRUE | D18: Total Stock | E18: SAP.MBEW.LBKUM | F18: LBKUM | G18: Total Valuated Stock | H18: decimal | J18: 13 | K18: 3 | P18: SAP.MAKT.SPRAS = 'E'
A19: ZB_G13_MATNR_Accounting1 | B19: Material Accounting data view 1 for a standard SAP ECC 6.0 system | C19: TRUE | D19: Total value | E19: SAP.MBEW.SALK3 | F19: SALK3 | G19: Value of Total Valuated Stock | H19: decimal | J19: 13 | K19: 2 | P19: SAP.MAKT.SPRAS = 'E'
A20: ZB_G13_MATNR_Accounting1 | B20: Material Accounting data view 1 for a standard SAP ECC 6.0 system | C20: TRUE | D20: Valuated Un | E20: SAP.MBEW.XBEWM | F20: XBEWM | G20: Valuation based on the batch-specific unit of measure | H20: varchar | I20: 1 | P20: SAP.MAKT.SPRAS = 'E'
A21: ZB_G13_MATNR_Accounting1 | B21: Material Accounting data view 1 for a standard SAP ECC 6.0 system | C21: TRUE | D21: Future price | E21: SAP.MBEW.ZKPRS | F21: ZKPRS | G21: Future price | H21: decimal | J21: 11 | K21: 2 | P21: SAP.MAKT.SPRAS = 'E'
A22: ZB_G13_MATNR_Accounting1 | B22: Material Accounting data view 1 for a standard SAP ECC 6.0 system | C22: TRUE | D22: Valid from | E22: SAP.MBEW.ZKDAT | F22: ZKDAT | G22: Date as of which the price is valid | H22: date | P22: SAP.MAKT.SPRAS = 'E'
A23: ZB_G13_MATNR_Accounting1 | B23: Material Accounting data view 1 for a standard SAP ECC 6.0 system | L23: SAP | M23: MAKT | P23: SAP.MAKT.SPRAS = 'E'
A24: ZB_G13_MATNR_Accounting1 | B24: Material Accounting data view 1 for a standard SAP ECC 6.0 system | L24: SAP | M24: MARA | P24: SAP.MAKT.SPRAS = 'E'
A25: ZB_G13_MATNR_Accounting1 | B25: Material Accounting data view 1 for a standard SAP ECC 6.0 system | L25: SAP | M25: MARC | P25: SAP.MAKT.SPRAS = 'E'
A26: ZB_G13_MATNR_Accounting1 | B26: Material Accounting data view 1 for a standard SAP ECC 6.0 system | L26: SAP | M26: MBEW | P26: SAP.MAKT.SPRAS = 'E'
A27: ZB_G13_MATNR_Accounting1 | B27: Material Accounting data view 1 for a standard SAP ECC 6.0 system | N27: inner | O27: ZB_G14_CUST_DunningRecipientReference | P27: SAP.MAKT.SPRAS = 'E'
A28: ZB_G13_MATNR_Accounting1 | B28: Material Accounting data view 1 for a standard SAP ECC 6.0 system | N28: inner | O28: SAP.MAKT.MATNR = SAP.MBEW.MATNR | P28: SAP.MAKT.SPRAS = 'E'
A29: ZB_G13_MATNR_Accounting1 | B29: Material Accounting data view 1 for a standard SAP ECC 6.0 system | N29: inner | O29: SAP.MAKT.MATNR = SAP.MARA.MATNR AND SAP.MARA.MATNR = SAP.MBEW.MATNR | P29: SAP.MAKT.SPRAS = 'E'
A30: ZB_G13_MATNR_Accounting1 | B30: Material Accounting data view 1 for a standard SAP ECC 6.0 system | N30: inner | O30: SAP.MAKT.MATNR = SAP.MARA.MATNR AND SAP.MARA.MATNR = SAP.MBEW.MATNR | P30: SAP.MAKT.SPRAS = 'E'
A31: ZB_G13_MATNR_Accounting1 | B31: Material Accounting data view 1 for a standard SAP ECC 6.0 system | N31: inner | O31: SAP.MAKT.MATNR = SAP.MARA.MATNR AND SAP.MARA.MATNR = SAP.MBEW.MATNR | P31: SAP.MAKT.SPRAS = 'E'
A32: ZB_G13_MATNR_Accounting1 | B32: Material Accounting data view 1 for a standard SAP ECC 6.0 system | N32: inner | O32: SAP.MAKT.MATNR = SAP.MARC.MATNR AND SAP.MARA.MATNR = SAP.MARC.MATNR AND SAP.MARC.MATNR = SAP.MBEW.MATNR | P32: SAP.MAKT.SPRAS = 'E'
A33: ZB_G13_MATNR_Accounting1 | B33: Material Accounting data view 1 for a standard SAP ECC 6.0 system | N33: inner | O33: SAP.MAKT.MATNR = SAP.MARC.MATNR AND SAP.MARA.MATNR = SAP.MARC.MATNR AND SAP.MARC.MATNR = SAP.MBEW.MATNR | P33: SAP.MAKT.SPRAS = 'E'
A34: ZB_G13_MATNR_Accounting1 | B34: Material Accounting data view 1 for a standard SAP ECC 6.0 system | N34: inner | O34: SAP.MAKT.MATNR = SAP.MARC.MATNR AND SAP.MARA.MATNR = SAP.MARC.MATNR AND SAP.MARC.MATNR = SAP.MBEW.MATNR | P34: SAP.MAKT.SPRAS = 'E'
A35: ZB_G13_MATNR_Accounting1 | B35: Material Accounting data view 1 for a standard SAP ECC 6.0 system | N35: inner | O35: SAP.MAKT.MATNR = SAP.MARC.MATNR AND SAP.MARA.MATNR = SAP.MARC.MATNR AND SAP.MARC.MATNR = SAP.MBEW.MATNR | P35: SAP.MAKT.SPRAS = 'E'
A36: ZB_G13_MATNR_Accounting2 | B36: Material Accounting data view 2 for a standard SAP ECC 6.0 system | C36: FALSE | D36: Material | E36: SAP.MARA.MATNR | F36: MATNR | H36: varchar | I36: 18 | P36: SAP.MAKT.SPRAS = 'E'
A37: ZB_G13_MATNR_Accounting2 | B37: Material Accounting data view 2 for a standard SAP ECC 6.0 system | C37: TRUE | D37: Description | E37: SAP.MAKT.MAKTX | F37: MAKTX | H37: varchar | I37: 40 | P37: SAP.MAKT.SPRAS = 'E'
A38: ZB_G13_MATNR_Accounting2 | B38: Material Accounting data view 2 for a standard SAP ECC 6.0 system | C38: TRUE | D38: Material Type | E38: SAP.MARA.MTART | F38: MTART | G38: Material Type | H38: varchar | I38: 4 | P38: SAP.MAKT.SPRAS = 'E'
A39: ZB_G13_MATNR_Accounting2 | B39: Material Accounting data view 2 for a standard SAP ECC 6.0 system | C39: FALSE | D39: Plant | E39: SAP.MARC.WERKS | F39: WERKS | H39: varchar | I39: 4 | P39: SAP.MAKT.SPRAS = 'E'
A40: ZB_G13_MATNR_Accounting2 | B40: Material Accounting data view 2 for a standard SAP ECC 6.0 system | C40: TRUE | D40: Tax price 1 | E40: SAP.MBEW.BWPRS | F40: BWPRS | G40: Valuation price based on tax law: level 1 | H40: decimal | J40: 11 | K40: 2 | P40: SAP.MAKT.SPRAS = 'E'
...

Sheet Consolidated
A1: num | B1: source | C1: entity | D1: new_brg1 | E1: new_brg2 | F1: new_brg3 | G1: brg1_old | H1: brg2_old | I1: brg3_old | J1: brg1 | K1: brg2 | L1: brg3 | M1: inerror | N1: inactive | O1: inactive_reason | P1: objname | Q1: new_objname | R1: rule_doc | S1: dimension | T1: old_dim | U1: parameter | V1: tabname | W1: fieldname | X1: fielddesc | Y1: lookup_tabname | Z1: lookup_fieldname | AA1: ISrule | AB1: ISfilter | AC1: QUACrule | AD1: where | AE1: resultfields | AF1: viewname | AG1: tableviewcode | AH1: notes
A2: Rule # | B2: Src | C2: Entity | D2: NEW_BRG1 | E2: NEW_BRG2 | F2: NEW_BRG3 | G2: BRG1 | H2: BRG2 | I2: BRG3 | J2: BRG33 | K2: BRG32 | L2: BRG4 | M2: In error state | N2: Inactive | O2: Inactive Reason | P2: Rule Name | Q2: New Rule Name | R2: Rule Desciption | S2: Rule Dimanesion | T2: old_dimension | U2: IS Parameter | V2: Table | W2: Field | X2: Field Description | Y2: Lookup Table | Z2: Lookup Field | AA2: Rule Expression | AB2: Filter Expression | AC2: QUAC rule | AD2: Where clause | AE2: Fields to Include in Result | AF2: View Name | AG2: Table View Code | AH2: Notes | AI2: RelatedRules | AJ2: PotentialRule | AK2: Rule # by Entity | AL2: Old Rule #
A3: 1 | B3: IS_RDS | C3: Material | D3: Logistics | E3: Material Master | F3: Plant Data for Material | G3: QualityManagement | J3: =VLOOKUP(V3,Table_to_BRG!A:D,3,FALSE) -> Plant data | K3: =VLOOKUP(V3,Table_to_BRG!A:D,2,FALSE) -> Plant | P3: ZB_G13_MATL_TargetQMSystemRef | Q3: =UPPER(LEFT(Table362[[#This Row],[Entity]],3))&RIGHT("00"&Table362[[#This Row],[Rule '# by Entity]],3)&"0_"&MID(SUBSTITUTE(Table362[[#This Row],[Rule Name]],"_","|",3),SEARCH("|",SUBSTITUTE(Table362[[#This Row],[Rule Name]],"_","|",3))+1,LEN(Table362[[#This Row],[Rule Name]])) -> MAT0780_TargetQMSystemRef | R3: Verify the Target QM System value exists in the QM system definition table. | S3: Consistency | U3: $P_I_TargetQMSystem | V3: MARC | W3: QSSYS | X3: Required QM System for Vendor | Y3: TQ02 | Z3: QSSYS | AA3: ="BEGIN RETURN exists('DS_IS_RDS', '"&Table362[[#This Row],[Lookup Table]]&"', '"&Table362[[#This Row],[Lookup Field]]&"', "&Table362[[#This Row],[IS Parameter]]&"); END" -> BEGIN RETURN exists('DS_IS_RDS', 'TQ02', 'QSSYS', $P_I_TargetQMSystem); END | AB3: =Table362[[#This Row],[IS Parameter]]&" IS NOT NULL AND rtrim("&Table362[[#This Row],[IS Parameter]]&", ' ') != ''" -> $P_I_TargetQMSystem IS NOT NULL AND rtrim($P_I_TargetQMSystem, ' ') != '' | AC3: QUAC.checkValueExists('{$lookuptabname}','{$lookupfieldname}') | AE3: =IF(Table362[[#This Row],[Entity]]="Customer","KUNNR",IF(Table362[[#This Row],[Entity]]="Vendor","LIFNR","MATNR"))&",WERKS"&","&Table362[[#This Row],[Field]] -> MATNR,WERKS,QSSYS | AF3: ="VW_"&Table362[[#This Row],[New Rule Name]] -> VW_MAT0780_TargetQMSystemRef | AG3: ="create view "&Table362[[#This Row],[View Name]]&" ( "&IF(Table362[[#This Row],[Entity]]="Customer","KUNNR",IF(Table362[[#This Row],[Entity]]="Vendor","LIFNR","MATNR"))&", WERKS, "&Table362[[#This Row],[Field]]&" ) as select "&IF(Table362[[#This Row],[Entity]]="Customer","KUNNR",IF(Table362[[#This Row],[Entity]]="Vendor","LIFNR","MATNR"))&", WERKS, "&Table362[[#This Row],[Field]]&" from "&Table362[[#This Row],[Table]] -> create view VW_MAT0780_TargetQMSystemRef ( MATNR, WERKS, QSSYS ) as select MATNR, WERKS, QSSYS from MARC | AH3: ="Potential rule: Verify that each "&Table362[[#This Row],[Lookup Table]]&"-"&Table362[[#This Row],[Lookup Field]]&" exists in "&Table362[[#This Row],[Table]]&"." -> Potential rule: Verify that each TQ02-QSSYS exists in MARC. | AI3: qms | AK3: 78 | AL3: 1 | AN3: Old view name formula1: "VW_"&MID(SUBSTITUTE([@[Rule Name]],"_","|",3),SEARCH("|",SUBSTITUTE([@[Rule Name]],"_","|",3))+1,LEN([@[Rule Name]]))
A4: 2 | B4: IS_RDS | C4: Customer | D4: Logistics | E4: Customer Master | F4: General Data in Customer Master | G4: GeneralData | H4: ExportData | J4: =VLOOKUP(V4,Table_to_BRG!A:D,3,FALSE) -> General data | K4: =VLOOKUP(V4,Table_to_BRG!A:D,2,FALSE) -> General | P4: ZB_G14_CUST_NuclearNonprolifIndicatorIsValid | Q4: =UPPER(LEFT(Table362[[#This Row],[Entity]],3))&RIGHT("00"&Table362[[#This Row],[Rule '# by Entity]],3)&"0_"&MID(SUBSTITUTE(Table362[[#This Row],[Rule Name]],"_","|",3),SEARCH("|",SUBSTITUTE(Table362[[#This Row],[Rule Name]],"_","|",3))+1,LEN(Table362[[#This Row],[Rule Name]])) -> CUS0360_NuclearNonprolifIndicatorIsValid | R4: Verify the nuclear nonproliferation indicator value is valid according to the appropriate reference domain or value range. | S4: Accuracy | T4: Consistency | U4: $P_I_NuclearNonProliferation | V4: KNA1 | W4: CCC02 | X4: Indicator for nuclear nonproliferation for legal control | AA4: BEGIN RETURN $P_I_NuclearNonProliferation = 'X'; END | AB4: =Table362[[#This Row],[IS Parameter]]&" IS NOT NULL AND "& Table362[[#This Row],[IS Parameter]]&" != ''" -> $P_I_NuclearNonProliferation IS NOT NULL AND $P_I_NuclearNonProliferation != '' | AC4: QUAC.checkValueIsDomainFixedValue() | AE4: =IF(Table362[[#This Row],[Entity]]="Customer","KUNNR",IF(Table362[[#This Row],[Entity]]="Vendor","LIFNR","MATNR"))&","&Table362[[#This Row],[Field]] -> KUNNR,CCC02 | AF4: ="VW_"&Table362[[#This Row],[New Rule Name]] -> VW_CUS0360_NuclearNonprolifIndicatorIsValid | AG4: ="create view "&Table362[[#This Row],[View Name]]&" ( "&IF(Table362[[#This Row],[Entity]]="Customer","KUNNR",IF(Table362[[#This Row],[Entity]]="Vendor","LIFNR","MATNR"))&", "&Table362[[#This Row],[Field]]&" ) as select "&IF(Table362[[#This Row],[Entity]]="Customer","KUNNR",IF(Table362[[#This Row],[Entity]]="Vendor","LIFNR","MATNR"))&", "&Table362[[#This Row],[Field]]&" from "&Table362[[#This Row],[Table]] -> create view VW_CUS0360_NuclearNonprolifIndicatorIsValid ( KUNNR, CCC02 ) as select KUNNR, CCC02 from KNA1 | AI4: expctrl | AK4: 36 | AN4: Old view name formula2: =RIGHT("00"&[@[Rule '#]],3)&"_"&IF([@Entity]="Material","MATL",LEFT(UPPER([@Entity]),4))&"_"&MID(SUBSTITUTE([@[Rule Name]],"_","|",3),SEARCH("|",SUBSTITUTE([@[Rule Name]],"_","|",3))+1,LEN([@[Rule Name]]))
A5: 2 | B5: IS_RDS | C5: Material | D5: Logistics | E5: Material Master | F5: Plant Data for Material | G5: GeneralData | J5: =VLOOKUP(V5,Table_to_BRG!A:D,3,FALSE) -> Plant data | K5: =VLOOKUP(V5,Table_to_BRG!A:D,2,FALSE) -> Plant | P5: ZB_G13_MATL_FairShareRuleIsValid | Q5: =UPPER(LEFT(Table362[[#This Row],[Entity]],3))&RIGHT("00"&Table362[[#This Row],[Rule '# by Entity]],3)&"0_"&MID(SUBSTITUTE(Table362[[#This Row],[Rule Name]],"_","|",3),SEARCH("|",SUBSTITUTE(Table362[[#This Row],[Rule Name]],"_","|",3))+1,LEN(Table362[[#This Row],[Rule Name]])) -> MAT0920_FairShareRuleIsValid | R5: Verify the fair share rule value is valid according to the appropriate reference domain or value range. | S5: Accuracy | T5: Consistency | U5: $P_I_FairShare_Rule | V5: MARC | W5: DPLFS | X5: Fair share rule | AA5: BEGIN RETURN $P_I_FairShare_Rule IN ('A', 'B', 'X'); END | AB5: =Table362[[#This Row],[IS Parameter]]&" IS NOT NULL AND rtrim("&Table362[[#This Row],[IS Parameter]]&", ' ') != ''" -> $P_I_FairShare_Rule IS NOT NULL AND rtrim($P_I_FairShare_Rule, ' ') != '' | AC5: QUAC.checkValueIsDomainFixedValue() | AE5: =IF(Table362[[#This Row],[Entity]]="Customer","KUNNR",IF(Table362[[#This Row],[Entity]]="Vendor","LIFNR","MATNR"))&",WERKS"&","&Table362[[#This Row],[Field]] -> MATNR,WERKS,DPLFS | AF5: ="VW_"&Table362[[#This Row],[New Rule Name]] -> VW_MAT0920_FairShareRuleIsValid | AG5: ="create view "&Table362[[#This Row],[View Name]]&" ( "&IF(Table362[[#This Row],[Entity]]="Customer","KUNNR",IF(Table362[[#This Row],[Entity]]="Vendor","LIFNR","MATNR"))&", WERKS, "&Table362[[#This Row],[Field]]&" ) as select "&IF(Table362[[#This Row],[Entity]]="Customer","KUNNR",IF(Table362[[#This Row],[Entity]]="Vendor","LIFNR","MATNR"))&", WERKS, "&Table362[[#This Row],[Field]]&" from "&Table362[[#This Row],[Table]] -> create view VW_MAT0920_FairShareRuleIsValid ( MATNR, WERKS, DPLFS ) as select MATNR, WERKS, DPLFS from MARC | AK5: 92
A6: 3 | B6: IS_RDS | C6: Material | D6: Logistics | E6: Material Master | F6: Plant Data for Material | G6: Costing1 | J6: =VLOOKUP(V6,Table_to_BRG!A:D,3,FALSE) -> Plant data | K6: =VLOOKUP(V6,Table_to_BRG!A:D,2,FALSE) -> Plant | P6: ZB_G13_MATL_TaskListTypeRef | Q6: =UPPER(LEFT(Table362[[#This Row],[Entity]],3))&RIGHT("00"&Table362[[#This Row],[Rule '# by Entity]],3)&"0_"&MID(SUBSTITUTE(Table362[[#This Row],[Rule Name]],"_","|",3),SEARCH("|",SUBSTITUTE(Table362[[#This Row],[Rule Name]],"_","|",3))+1,LEN(Table362[[#This Row],[Rule Name]])) -> MAT0820_TaskListTypeRef | R6: Verify the task list type value exists in the Task List Types table. | S6: Consistency | U6: $P_I_TaskListType | V6: MARC | W6: PLNTY | X6: Task List Type | Y6: TCA01 | Z6: PLNTY | AA6: ="BEGIN RETURN exists('DS_IS_RDS', '"&Table362[[#This Row],[Lookup Table]]&"', '"&Table362[[#This Row],[Lookup Field]]&"', "&Table362[[#This Row],[IS Parameter]]&"); END" -> BEGIN RETURN exists('DS_IS_RDS', 'TCA01', 'PLNTY', $P_I_TaskListType); END | AB6: =Table362[[#This Row],[IS Parameter]]&" IS NOT NULL AND rtrim("&Table362[[#This Row],[IS Parameter]]&", ' ') != ''" -> $P_I_TaskListType IS NOT NULL AND rtrim($P_I_TaskListType, ' ') != '' | AC6: QUAC.checkValueExists('{$lookuptabname}','{$lookupfieldname}') | AE6: =IF(Table362[[#This Row],[Entity]]="Customer","KUNNR",IF(Table362[[#This Row],[Entity]]="Vendor","LIFNR","MATNR"))&",WERKS"&","&Table362[[#This Row],[Field]] -> MATNR,WERKS,PLNTY | AF6: ="VW_"&Table362[[#This Row],[New Rule Name]] -> VW_MAT0820_TaskListTypeRef | AG6: ="create view "&Table362[[#This Row],[View Name]]&" ( "&IF(Table362[[#This Row],[Entity]]="Customer","KUNNR",IF(Table362[[#This Row],[Entity]]="Vendor","LIFNR","MATNR"))&", WERKS, "&Table362[[#This Row],[Field]]&" ) as select "&IF(Table362[[#This Row],[Entity]]="Customer","KUNNR",IF(Table362[[#This Row],[Entity]]="Vendor","LIFNR","MATNR"))&", WERKS, "&Table362[[#This Row],[Field]]&" from "&Table362[[#This Row],[Table]] -> create view VW_MAT0820_TaskListTypeRef ( MATNR, WERKS, PLNTY ) as select MATNR, WERKS, PLNTY from MARC | AH6: ="Potential rule: Verify that each "&Table362[[#This Row],[Lookup Table]]&"-"&Table362[[#This Row],[Lookup Field]]&" exists in "&Table362[[#This Row],[Table]]&"." -> Potential rule: Verify that each TCA01-PLNTY exists in MARC. | AI6: tasklist | AK6: 82
A7: 4 | B7: IS_RDS | C7: Customer | D7: Logistics | E7: Customer Master | F7: General Data in Customer Master | G7: GeneralData | H7: Control | J7: =VLOOKUP(V7,Table_to_BRG!A:D,3,FALSE) -> General data | K7: =VLOOKUP(V7,Table_to_BRG!A:D,2,FALSE) -> General | P7: ZB_G14_CUST_TradingPartnerRef | Q7: =UPPER(LEFT(Table362[[#This Row],[Entity]],3))&RIGHT("00"&Table362[[#This Row],[Rule '# by Entity]],3)&"0_"&MID(SUBSTITUTE(Table362[[#This Row],[Rule Name]],"_","|",3),SEARCH("|",SUBSTITUTE(Table362[[#This Row],[Rule Name]],"_","|",3))+1,LEN(Table362[[#This Row],[Rule Name]])) -> CUS0250_TradingPartnerRef | R7: Verify the customer trading partner value exists in the Global Company Data (for KONS Ledger) table. | S7: Completeness | T7: Consistency | U7: $P_I_TradingPartner | V7: KNA1 | W7: VBUND | X7: Company ID of trading partner | Y7: T880 | Z7: RCOMP | AA7: ="BEGIN RETURN exists('DS_IS_RDS', '"&Table362[[#This Row],[Lookup Table]]&"', '"&Table362[[#This Row],[Lookup Field]]&"', "&Table362[[#This Row],[IS Parameter]]&"); END" -> BEGIN RETURN exists('DS_IS_RDS', 'T880', 'RCOMP', $P_I_TradingPartner); END | AB7: =Table362[[#This Row],[IS Parameter]]&" IS NOT NULL AND "& Table362[[#This Row],[IS Parameter]]&" != ''" -> $P_I_TradingPartner IS NOT NULL AND $P_I_TradingPartner != '' | AC7: QUAC.checkValueExists('{$lookuptabname}','{$lookupfieldname}') | AE7: =IF(Table362[[#This Row],[Entity]]="Customer","KUNNR",IF(Table362[[#This Row],[Entity]]="Vendor","LIFNR","MATNR"))&","&Table362[[#This Row],[Field]] -> KUNNR,VBUND | AF7: ="VW_"&Table362[[#This Row],[New Rule Name]] -> VW_CUS0250_TradingPartnerRef | AG7: ="create view "&Table362[[#This Row],[View Name]]&" ( "&IF(Table362[[#This Row],[Entity]]="Customer","KUNNR",IF(Table362[[#This Row],[Entity]]="Vendor","LIFNR","MATNR"))&", "&Table362[[#This Row],[Field]]&" ) as select "&IF(Table362[[#This Row],[Entity]]="Customer","KUNNR",IF(Table362[[#This Row],[Entity]]="Vendor","LIFNR","MATNR"))&", "&Table362[[#This Row],[Field]]&" from "&Table362[[#This Row],[Table]] -> create view VW_CUS0250_TradingPartnerRef ( KUNNR, VBUND ) as select KUNNR, VBUND from KNA1 | AH7: ="Potential rule: Verify that each "&Table362[[#This Row],[Lookup Table]]&"-"&Table362[[#This Row],[Lookup Field]]&" exists in "&Table362[[#This Row],[Table]]&"." -> Potential rule: Verify that each T880-RCOMP exists in KNA1. | AI7: tradpart4c | AK7: 25
A8: 6 | B8: IS_RDS | C8: Vendor | D8: SalesAndDistribution | E8: Billing | F8: Customer Master Licenses | G8: Master Licenses | I8: License | J8: =VLOOKUP(V8,Table_to_BRG!A:D,3,FALSE) -> #N/A | K8: =VLOOKUP(V8,Table_to_BRG!A:D,2,FALSE) -> #N/A | N8: x | O8: Vendor master data license table not found | P8: ZB_G15_VNDR_LicensevalidToDatePopulated | R8: Rule to check if the License valid to date for Business Partner / Customer / Vendor exists | S8: Completeness | U8: $P_I_LicenseValidToDate | W8: DATBI | X8: Valid To Date | AA8: BEGIN RETURN $P_I_LicenseValidToDate IS NOT NULL AND $P_I_LicenseValidToDate != to_date('', 'yyyy.mm.dd'); END | AC8: QUAC.checkValueIsNotEmpty() | AH8: There does not appear to be a vendor master license table in ECC, but CRM has a table OIHL with fields for both customer and vendor numbers. | AI8: license03v
A9: 5 | B9: IS_RDS | C9: Customer | D9: Logistics | E9: Customer Master | F9: General Data in Customer Master | G9: GeneralData | H9: SalesInformation | J9: =VLOOKUP(V9,Table_to_BRG!A:D,3,FALSE) -> General data | K9: =VLOOKUP(V9,Table_to_BRG!A:D,2,FALSE) -> General | P9: ZB_G14_CUST_SalesCurrencyPopulated | Q9: =UPPER(LEFT(Table362[[#This Row],[Entity]],3))&RIGHT("00"&Table362[[#This Row],[Rule '# by Entity]],3)&"0_"&MID(SUBSTITUTE(Table362[[#This Row],[Rule Name]],"_","|",3),SEARCH("|",SUBSTITUTE(Table362[[#This Row],[Rule Name]],"_","|",3))+1,LEN(Table362[[#This Row],[Rule Name]])) -> CUS0290_SalesCurrencyPopulated | R9: Verify the customer sales currency field is not empty. | S9: Completeness | U9: $P_I_Currency | V9: KNA1 | W9: UWAER | X9: Currency of sales figure | AA9: BEGIN RETURN $P_I_Currency IS NOT NULL AND $P_I_Currency != ''; END | AC9: QUAC.checkValueIsNotEmpty() | AE9: =IF(Table362[[#This Row],[Entity]]="Customer","KUNNR",IF(Table362[[#This Row],[Entity]]="Vendor","LIFNR","MATNR"))&","&Table362[[#This Row],[Field]] -> KUNNR,UWAER | AF9: ="VW_"&Table362[[#This Row],[New Rule Name]] -> VW_CUS0290_SalesCurrencyPopulated | AG9: ="create view "&Table362[[#This Row],[View Name]]&" ( "&IF(Table362[[#This Row],[Entity]]="Customer","KUNNR",IF(Table362[[#This Row],[Entity]]="Vendor","LIFNR","MATNR"))&", "&Table362[[#This Row],[Field]]&" ) as select "&IF(Table362[[#This Row],[Entity]]="Customer","KUNNR",IF(Table362[[#This Row],[Entity]]="Vendor","LIFNR","MATNR"))&", "&Table362[[#This Row],[Field]]&" from "&Table362[[#This Row],[Table]] -> create view VW_CUS0290_SalesCurrencyPopulated ( KUNNR, UWAER ) as select KUNNR, UWAER from KNA1 | AI9: salescurr | AK9: 29
A10: 7 | B10: IS_RDS | C10: Material | D10: Logistics | E10: Material Master | F10: Plant Data for Material | G10: SalesGeneral | H10: PlantData | J10: =VLOOKUP(V10,Table_to_BRG!A:D,3,FALSE) -> Plant data | K10: =VLOOKUP(V10,Table_to_BRG!A:D,2,FALSE) -> Plant | P10: ZB_G13_MATL_AvailabilityCheckPopulated | Q10: =UPPER(LEFT(Table362[[#This Row],[Entity]],3))&RIGHT("00"&Table362[[#This Row],[Rule '# by Entity]],3)&"0_"&MID(SUBSTITUTE(Table362[[#This Row],[Rule Name]],"_","|",3),SEARCH("|",SUBSTITUTE(Table362[[#This Row],[Rule Name]],"_","|",3))+1,LEN(Table362[[#This Row],[Rule Name]])) -> MAT0600_AvailabilityCheckPopulated | R10: Verify the availability check field is not empty. | S10: Completeness | U10: $P_I_AvailabilityCheck | V10: MARC | W10: MTVFP | X10: Checking group for availability check | AA10: BEGIN RETURN $P_I_AvailabilityCheck IS NOT NULL AND $P_I_AvailabilityCheck != ''; END | AC10: QUAC.checkValueIsNotEmpty() | AE10: =IF(Table362[[#This Row],[Entity]]="Customer","KUNNR",IF(Table362[[#This Row],[Entity]]="Vendor","LIFNR","MATNR"))&",WERKS"&","&Table362[[#This Row],[Field]] -> MATNR,WERKS,MTVFP | AF10: ="VW_"&Table362[[#This Row],[New Rule Name]] -> VW_MAT0600_AvailabilityCheckPopulated | AG10: ="create view "&Table362[[#This Row],[View Name]]&" ( "&IF(Table362[[#This Row],[Entity]]="Customer","KUNNR",IF(Table362[[#This Row],[Entity]]="Vendor","LIFNR","MATNR"))&", WERKS, "&Table362[[#This Row],[Field]]&" ) as select "&IF(Table362[[#This Row],[Entity]]="Customer","KUNNR",IF(Table362[[#This Row],[Entity]]="Vendor","LIFNR","MATNR"))&", WERKS, "&Table362[[#This Row],[Field]]&" from "&Table362[[#This Row],[Table]] -> create view VW_MAT0600_AvailabilityCheckPopulated ( MATNR, WERKS, MTVFP ) as select MATNR, WERKS, MTVFP from MARC | AI10: availcheck | AK10: 60 | AL10: 3
A11: 9 | B11: IS_RDS | C11: Vendor | J11: =VLOOKUP(V11,Table_to_BRG!A:D,3,FALSE) -> Customer sales data | K11: =VLOOKUP(V11,Table_to_BRG!A:D,2,FALSE) -> Sales | N11: x | O11: Vendor master data statistics group table not found | P11: ZB_G15_VNDR_StatisticeGroupRef | R11: Verify the vendor Statistics Group exists. | S11: Consistency | U11: $P_I_StatisticsGroup | V11: KNVV | W11: VERSG | X11: Customer Statistics Group | Y11: TVSD | Z11: STGKU | AA11: ="BEGIN RETURN exists('DS_IS_RDS', '"&Table362[[#This Row],[Lookup Table]]&"', '"&Table362[[#This Row],[Lookup Field]]&"', "&Table362[[#This Row],[IS Parameter]]&"); END" -> BEGIN RETURN exists('DS_IS_RDS', 'TVSD', 'STGKU', $P_I_StatisticsGroup); END | AC11: QUAC.checkValueExists('{$lookuptabname}','{$lookupfieldname}') | AE11: =IF(Table362[[#This Row],[Entity]]="Customer","KUNNR",IF(Table362[[#This Row],[Entity]]="Vendor","LIFNR","MATNR"))&","&Table362[[#This Row],[Field]] -> LIFNR,VERSG | AG11: ="create view "&Table362[[#This Row],[View Name]]&" as select "&IF(Table362[[#This Row],[Entity]]="Customer","KUNNR",IF(Table362[[#This Row],[Entity]]="Vendor","LIFNR","MATNR"))&", "&Table362[[#This Row],[Field]]&" from "&Table362[[#This Row],[Table]] -> create view as select LIFNR, VERSG from KNVV | AI11: statgrp9v
A12: 10 | B12: IS_RDS | C12: Vendor | D12: Finance | E12: Financial Accounting | F12: Vendor Master (General Section) | G12: GeneralData | H12: Control | I12: Tax | J12: =VLOOKUP(V12,Table_to_BRG!A:D,3,FALSE) -> General data | K12: =VLOOKUP(V12,Table_to_BRG!A:D,2,FALSE) -> General | N12: x | O12: LFA1-STCD1 does not have a lookup table reference | P12: See Note ZB_G15_VNDR_TaxNumberRef | R12: Verify the tax Number value exists in the | S12: Consistency | U12: $P_I_TaxNumber | V12: LFA1 | W12: STCD1 | X12: Tax Number 1 | Y12: M_KREDA | Z12: LIFNR | AA12: ="BEGIN RETURN exists('DS_IS_RDS', '"&Table362[[#This Row],[Lookup Table]]&"', '"&Table362[[#This Row],[Lookup Field]]&"', "&Table362[[#This Row],[IS Parameter]]&"); END" -> BEGIN RETURN exists('DS_IS_RDS', 'M_KREDA', 'LIFNR', $P_I_TaxNumber); END | AC12: QUAC.checkValueExists('{$lookuptabname}','{$lookupfieldname}') | AI12: taxnumber
A13: 8 | B13: IS_RDS | C13: Customer | D13: Finance | E13: Financial Accounting | F13: Customer Master (Company Code) | G13: CompanyCodeData | H13: CompanyCode | J13: =VLOOKUP(V13,Table_to_BRG!A:D,3,FALSE) -> Company Code data | K13: =VLOOKUP(V13,Table_to_BRG!A:D,2,FALSE) -> Company Code | P13: ZB_G14_CUST_CompanyCodePopulated | Q13: =UPPER(LEFT(Table362[[#This Row],[Entity]],3))&RIGHT("00"&Table362[[#This Row],[Rule '# by Entity]],3)&"0_"&MID(SUBSTITUTE(Table362[[#This Row],[Rule Name]],"_","|",3),SEARCH("|",SUBSTITUTE(Table362[[#This Row],[Rule Name]],"_","|",3))+1,LEN(Table362[[#This Row],[Rule Name]])) -> CUS0390_CompanyCodePopulated | R13: Verify the company code field is not empty. | S13: Completeness | U13: $P_I_CompanyCode | V13: KNB1 | W13: BUKRS | X13: Company Code | AA13: BEGIN RETURN $P_I_CompanyCode IS NOT NULL AND $P_I_CompanyCode != ''; END | AC13: QUAC.checkValueIsNotEmpty() | AE13: =IF(Table362[[#This Row],[Entity]]="Customer","KUNNR",IF(Table362[[#This Row],[Entity]]="Vendor","LIFNR","MATNR"))&","&Table362[[#This Row],[Field]] -> KUNNR,BUKRS | AF13: ="VW_"&Table362[[#This Row],[New Rule Name]] -> VW_CUS0390_CompanyCodePopulated | AG13: ="create view "&Table362[[#This Row],[View Name]]&" ( "&IF(Table362[[#This Row],[Entity]]="Customer","KUNNR",IF(Table362[[#This Row],[Entity]]="Vendor","LIFNR","MATNR"))&", "&Table362[[#This Row],[Field]]&" ) as select "&IF(Table362[[#This Row],[Entity]]="Customer","KUNNR",IF(Table362[[#This Row],[Entity]]="Vendor","LIFNR","MATNR"))&", "&Table362[[#This Row],[Field]]&" from "&Table362[[#This Row],[Table]] -> create view VW_CUS0390_CompanyCodePopulated ( KUNNR, BUKRS ) as select KUNNR, BUKRS from KNB1 | AI13: compcode8c | AK13: 39
A14: 11 | B14: IS_RDS | C14: Material | D14: Logistics | E14: Material Master | F14: Plant Data for Material | G14: MatlReqPlanning | H14: MRP1 | J14: =VLOOKUP(V14,Table_to_BRG!A:D,3,FALSE) -> Plant data | K14: =VLOOKUP(V14,Table_to_BRG!A:D,2,FALSE) -> Plant | P14: ZB_G13_MATL_MRPTypeRef | Q14: =UPPER(LEFT(Table362[[#This Row],[Entity]],3))&RIGHT("00"&Table362[[#This Row],[Rule '# by Entity]],3)&"0_"&MID(SUBSTITUTE(Table362[[#This Row],[Rule Name]],"_","|",3),SEARCH("|",SUBSTITUTE(Table362[[#This Row],[Rule Name]],"_","|",3))+1,LEN(Table362[[#This Row],[Rule Name]])) -> MAT0410_MRPTypeRef | R14: Verify the MRP Type value exists in the MRP Type table. | S14: Consistency | U14: $P_I_MRPType | V14: MARC | W14: DISMM | X14: MRP Type | Y14: T438A | Z14: DISMM | AA14: ="BEGIN RETURN exists('DS_IS_RDS', '"&Table362[[#This Row],[Lookup Table]]&"', '"&Table362[[#This Row],[Lookup Field]]&"', "&Table362[[#This Row],[IS Parameter]]&"); END" -> BEGIN RETURN exists('DS_IS_RDS', 'T438A', 'DISMM', $P_I_MRPType); END | AB14: =Table362[[#This Row],[IS Parameter]]&" IS NOT NULL AND rtrim("&Table362[[#This Row],[IS Parameter]]&", ' ') != ''" -> $P_I_MRPType IS NOT NULL AND rtrim($P_I_MRPType, ' ') != '' | AC14: QUAC.checkValueExists('{$lookuptabname}','{$lookupfieldname}') | AE14: =IF(Table362[[#This Row],[Entity]]="Customer","KUNNR",IF(Table362[[#This Row],[Entity]]="Vendor","LIFNR","MATNR"))&",WERKS"&","&Table362[[#This Row],[Field]] -> MATNR,WERKS,DISMM | AF14: ="VW_"&Table362[[#This Row],[New Rule Name]] -> VW_MAT0410_MRPTypeRef | AG14: ="create view "&Table362[[#This Row],[View Name]]&" ( "&IF(Table362[[#This Row],[Entity]]="Customer","KUNNR",IF(Table362[[#This Row],[Entity]]="Vendor","LIFNR","MATNR"))&", WERKS, "&Table362[[#This Row],[Field]]&" ) as select "&IF(Table362[[#This Row],[Entity]]="Customer","KUNNR",IF(Table362[[#This Row],[Entity]]="Vendor","LIFNR","MATNR"))&", WERKS, "&Table362[[#This Row],[Field]]&" from "&Table362[[#This Row],[Table]] -> create view VW_MAT0410_MRPTypeRef ( MATNR, WERKS, DISMM ) as select MATNR, WERKS, DISMM from MARC | AI14: mrpttype | AK14: 41
A15: 12 | B15: IS_RDS | C15: Customer | D15: SalesAndDistribution | E15: Billing | F15: Customer Master Tax Indicator | G15: SalesAreaData | H15: BillingDocuments | I15: Tax | J15: =VLOOKUP(V15,Table_to_BRG!A:D,3,FALSE) -> Tax data | K15: =VLOOKUP(V15,Table_to_BRG!A:D,2,FALSE) -> Tax indicator | P15: ZB_G14_CUST_TaxClassificationPopulated | Q15: =UPPER(LEFT(Table362[[#This Row],[Entity]],3))&RIGHT("00"&Table362[[#This Row],[Rule '# by Entity]],3)&"0_"&MID(SUBSTITUTE(Table362[[#This Row],[Rule Name]],"_","|",3),SEARCH("|",SUBSTITUTE(Table362[[#This Row],[Rule Name]],"_","|",3))+1,LEN(Table362[[#This Row],[Rule Name]])) -> CUS0740_TaxClassificationPopulated | R15: Verify the tax classification field is not empty. | S15: Completeness | U15: $P_I_TaxClassification | V15: KNVI | W15: TAXKD | X15: Tax classification for customer | AA15: BEGIN RETURN $P_I_TaxClassification IS NOT NULL AND $P_I_TaxClassification != ''; END | AC15: QUAC.checkValueIsNotEmpty() | AE15: =IF(Table362[[#This Row],[Entity]]="Customer","KUNNR",IF(Table362[[#This Row],[Entity]]="Vendor","LIFNR","MATNR"))&",ALAND,TATYP"&","&Table362[[#This Row],[Field]] -> KUNNR,ALAND,TATYP,TAXKD | AF15: ="VW_"&Table362[[#This Row],[New Rule Name]] -> VW_CUS0740_TaxClassificationPopulated | AG15: ="create view "&Table362[[#This Row],[View Name]]&" ( "&IF(Table362[[#This Row],[Entity]]="Customer","KUNNR",IF(Table362[[#This Row],[Entity]]="Vendor","LIFNR","MATNR"))&", ALAND, TATYP, "&Table362[[#This Row],[Field]]&" ) as select "&IF(Table362[[#This Row],[Entity]]="Customer","KUNNR",IF(Table362[[#This Row],[Entity]]="Vendor","LIFNR","MATNR"))&", ALAND, TATYP, "&Table362[[#This Row],[Field]]&" from "&Table362[[#This Row],[Table]] -> create view VW_CUS0740_TaxClassificationPopulated ( KUNNR, ALAND, TATYP, TAXKD ) as select KUNNR, ALAND, TATYP, TAXKD from KNVI | AI15: taxclass12c | AK15: 74
A16: 13 | B16: IS_RDS | C16: Customer | D16: Logistics | E16: Customer Master | F16: Customer Master Sales Data | G16: SalesAreaData | H16: Sales | J16: =VLOOKUP(V16,Table_to_BRG!A:D,3,FALSE) -> Customer sales data | K16: =VLOOKUP(V16,Table_to_BRG!A:D,2,FALSE) -> Sales | P16: ZB_G14_CUST_DivisionPopulated | Q16: =UPPER(LEFT(Table362[[#This Row],[Entity]],3))&RIGHT("00"&Table362[[#This Row],[Rule '# by Entity]],3)&"0_"&MID(SUBSTITUTE(Table362[[#This Row],[Rule Name]],"_","|",3),SEARCH("|",SUBSTITUTE(Table362[[#This Row],[Rule Name]],"_","|",3))+1,LEN(Table362[[#This Row],[Rule Name]])) -> CUS0910_DivisionPopulated | R16: Verify the division field is not empty. | S16: Completeness | U16: $P_I_Division | V16: KNVV | W16: SPART | X16: Division | AA16: BEGIN RETURN $P_I_Division IS NOT NULL AND $P_I_Division != ''; END | AC16: QUAC.checkValueIsNotEmpty() | AE16: KUNNR,VKORG,VTWEG,SPART | AF16: ="VW_"&Table362[[#This Row],[New Rule Name]] -> VW_CUS0910_DivisionPopulated | AG16: ="create view "&Table362[[#This Row],[View Name]]&" ( "&IF(Table362[[#This Row],[Entity]]="Customer","KUNNR",IF(Table362[[#This Row],[Entity]]="Vendor","LIFNR","MATNR"))&", VKORG, VTWEG, "&Table362[[#This Row],[Field]]&" ) as select "&IF(Table362[[#This Row],[Entity]]="Customer","KUNNR",IF(Table362[[#This Row],[Entity]]="Vendor","LIFNR","MATNR"))&", VKORG, VTWEG, "&Table362[[#This Row],[Field]]&" from "&Table362[[#This Row],[Table]] -> create view VW_CUS0910_DivisionPopulated ( KUNNR, VKORG, VTWEG, SPART ) as select KUNNR, VKORG, VTWEG, SPART from KNVV | AI16: division | AK16: 91
A17: 14 | B17: IS_RDS | C17: Material | D17: Logistics | E17: Material Master | F17: General Material Data | G17: SalesGeneral | H17: PlantData | J17: =VLOOKUP(V17,Table_to_BRG!A:D,3,FALSE) -> General data | K17: =VLOOKUP(V17,Table_to_BRG!A:D,2,FALSE) -> General | P17: ZB_G13_MATL_TransportationGroupPopulated | Q17: =UPPER(LEFT(Table362[[#This Row],[Entity]],3))&RIGHT("00"&Table362[[#This Row],[Rule '# by Entity]],3)&"0_"&MID(SUBSTITUTE(Table362[[#This Row],[Rule Name]],"_","|",3),SEARCH("|",SUBSTITUTE(Table362[[#This Row],[Rule Name]],"_","|",3))+1,LEN(Table362[[#This Row],[Rule Name]])) -> MAT0160_TransportationGroupPopulated | R17: Verify the transportation group field Is not empty. | S17: Completeness | U17: $P_I_TransportationGroup | V17: MARA | W17: TRAGR | X17: Transportation group | AA17: BEGIN RETURN $P_I_TransportationGroup IS NOT NULL AND $P_I_TransportationGroup != ''; END | AC17: QUAC.checkValueIsNotEmpty() | AE17: =IF(Table362[[#This Row],[Entity]]="Customer","KUNNR",IF(Table362[[#This Row],[Entity]]="Vendor","LIFNR","MATNR"))&","&Table362[[#This Row],[Field]] -> MATNR,TRAGR | AF17: ="VW_"&Table362[[#This Row],[New Rule Name]] -> VW_MAT0160_TransportationGroupPopulated | AG17: ="create view "&Table362[[#This Row],[View Name]]&" ( "&IF(Table362[[#This Row],[Entity]]="Customer","KUNNR",IF(Table362[[#This Row],[Entity]]="Vendor","LIFNR","MATNR"))&", "&Table362[[#This Row],[Field]]&" ) as select "&IF(Table362[[#This Row],[Entity]]="Customer","KUNNR",IF(Table362[[#This Row],[Entity]]="Vendor","LIFNR","MATNR"))&", "&Table362[[#This Row],[Field]]&" from "&Table362[[#This Row],[Table]] -> create view VW_MAT0160_TransportationGroupPopulated ( MATNR, TRAGR ) as select MATNR, TRAGR from MARA | AI17: transgrp | AK17: 16
A18: 15 | B18: IS_RDS | C18: Material | D18: Logistics | E18: Material Master | F18: Plant Data for Material | G18: MatlReqPlanning | H18: MRP2 | J18: =VLOOKUP(V18,Table_to_BRG!A:D,3,FALSE) -> Plant data | K18: =VLOOKUP(V18,Table_to_BRG!A:D,2,FALSE) -> Plant | P18: ZB_G13_MATL_SchedulingMarginKeyRef | Q18: =UPPER(LEFT(Table362[[#This Row],[Entity]],3))&RIGHT("00"&Table362[[#This Row],[Rule '# by Entity]],3)&"0_"&MID(SUBSTITUTE(Table362[[#This Row],[Rule Name]],"_","|",3),SEARCH("|",SUBSTITUTE(Table362[[#This Row],[Rule Name]],"_","|",3))+1,LEN(Table362[[#This Row],[Rule Name]])) -> MAT0540_SchedulingMarginKeyRef | R18: Verify the scheduling margin key value exists in the Floats for Scheduling table. | S18: Consistency | U18: $P_I_SchedulingMarginKey | V18: MARC | W18: FHORI | X18: Scheduling Margin Key for Floats | Y18: T436A | Z18: FHORI | AA18: ="BEGIN RETURN exists('DS_IS_RDS', '"&Table362[[#This Row],[Lookup Table]]&"', '"&Table362[[#This Row],[Lookup Field]]&"', "&Table362[[#This Row],[IS Parameter]]&"); END" -> BEGIN RETURN exists('DS_IS_RDS', 'T436A', 'FHORI', $P_I_SchedulingMarginKey); END | AB18: =Table362[[#This Row],[IS Parameter]]&" IS NOT NULL AND rtrim("&Table362[[#This Row],[IS Parameter]]&", ' ') != ''" -> $P_I_SchedulingMarginKey IS NOT NULL AND rtrim($P_I_SchedulingMarginKey, ' ') != '' | AC18: QUAC.checkValueExists('{$lookuptabname}','{$lookupfieldname}') | AE18: =IF(Table362[[#This Row],[Entity]]="Customer","KUNNR",IF(Table362[[#This Row],[Entity]]="Vendor","LIFNR","MATNR"))&",WERKS"&","&Table362[[#This Row],[Field]] -> MATNR,WERKS,FHORI | AF18: ="VW_"&Table362[[#This Row],[New Rule Name]] -> VW_MAT0540_SchedulingMarginKeyRef | AG18: ="create view "&Table362[[#This Row],[View Name]]&" ( "&IF(Table362[[#This Row],[Entity]]="Customer","KUNNR",IF(Table362[[#This Row],[Entity]]="Vendor","LIFNR","MATNR"))&", WERKS, "&Table362[[#This Row],[Field]]&" ) as select "&IF(Table362[[#This Row],[Entity]]="Customer","KUNNR",IF(Table362[[#This Row],[Entity]]="Vendor","LIFNR","MATNR"))&", WERKS, "&Table362[[#This Row],[Field]]&" from "&Table362[[#This Row],[Table]] -> create view VW_MAT0540_SchedulingMarginKeyRef ( MATNR, WERKS, FHORI ) as select MATNR, WERKS, FHORI from MARC | AI18: scheduling | AK18: 54
A19: 16 | B19: IS_RDS | C19: Material | D19: Logistics | E19: Material Master | F19: Plant Data for Material | G19: SalesGeneral | H19: PlantData | J19: =VLOOKUP(V19,Table_to_BRG!A:D,3,FALSE) -> Plant data | K19: =VLOOKUP(V19,Table_to_BRG!A:D,2,FALSE) -> Plant | P19: ZB_G13_MATL_LoadingGroupPopulated | Q19: =UPPER(LEFT(Table362[[#This Row],[Entity]],3))&RIGHT("00"&Table362[[#This Row],[Rule '# by Entity]],3)&"0_"&MID(SUBSTITUTE(Table362[[#This Row],[Rule Name]],"_","|",3),SEARCH("|",SUBSTITUTE(Table362[[#This Row],[Rule Name]],"_","|",3))+1,LEN(Table362[[#This Row],[Rule Name]])) -> MAT0570_LoadingGroupPopulated | R19: Verify the loading group field is not empty. | S19: Completeness | U19: $P_I_LoadingGroup | V19: MARC | W19: LADGR | X19: Loading group | AA19: BEGIN RETURN $P_I_LoadingGroup IS NOT NULL AND $P_I_LoadingGroup != ''; END | AC19: QUAC.checkValueIsNotEmpty() | AE19: =IF(Table362[[#This Row],[Entity]]="Customer","KUNNR",IF(Table362[[#This Row],[Entity]]="Vendor","LIFNR","MATNR"))&",WERKS"&","&Table362[[#This Row],[Field]] -> MATNR,WERKS,LADGR | AF19: ="VW_"&Table362[[#This Row],[New Rule Name]] -> VW_MAT0570_LoadingGroupPopulated | AG19: ="create view "&Table362[[#This Row],[View Name]]&" ( "&IF(Table362[[#This Row],[Entity]]="Customer","KUNNR",IF(Table362[[#This Row],[Entity]]="Vendor","LIFNR","MATNR"))&", WERKS, "&Table362[[#This Row],[Field]]&" ) as select "&IF(Table362[[#This Row],[Entity]]="Customer","KUNNR",IF(Table362[[#This Row],[Entity]]="Vendor","LIFNR","MATNR"))&", WERKS, "&Table362[[#This Row],[Field]]&" from "&Table362[[#This Row],[Table]] -> create view VW_MAT0570_LoadingGroupPopulated ( MATNR, WERKS, LADGR ) as select MATNR, WERKS, LADGR from MARC | AI19: loadgrp | AK19: 57
A20: 17 | B20: IS_RDS | C20: Customer | D20: Logistics | E20: Customer Master | F20: General Data in Customer Master | G20: GeneralData | H20: ExportData | J20: =VLOOKUP(V20,Table_to_BRG!A:D,3,FALSE) -> General data | K20: =VLOOKUP(V20,Table_to_BRG!A:D,2,FALSE) -> General | P20: ZB_G14_CUST_NationalSecurityIndicatorIsValid | Q20: =UPPER(LEFT(Table362[[#This Row],[Entity]],3))&RIGHT("00"&Table362[[#This Row],[Rule '# by Entity]],3)&"0_"&MID(SUBSTITUTE(Table362[[#This Row],[Rule Name]],"_","|",3),SEARCH("|",SUBSTITUTE(Table362[[#This Row],[Rule Name]],"_","|",3))+1,LEN(Table362[[#This Row],[Rule Name]])) -> CUS0370_NationalSecurityIndicatorIsValid | R20: Verify the national security indicator value is valid according to the appropriate reference domain or value range. | S20: Accuracy | T20: Consistency | U20: $P_I_NationalSecurityInd | V20: KNA1 | W20: CCC03 | X20: Indicator for national security for legal control | AA20: BEGIN RETURN $P_I_NationalSecurityInd = 'X'; END | AB20: =Table362[[#This Row],[IS Parameter]]&" IS NOT NULL AND "& Table362[[#This Row],[IS Parameter]]&" != ''" -> $P_I_NationalSecurityInd IS NOT NULL AND $P_I_NationalSecurityInd != '' | AC20: QUAC.checkValueIsDomainFixedValue() | AE20: =IF(Table362[[#This Row],[Entity]]="Customer","KUNNR",IF(Table362[[#This Row],[Entity]]="Vendor","LIFNR","MATNR"))&","&Table362[[#This Row],[Field]] -> KUNNR,CCC03 | AF20: ="VW_"&Table362[[#This Row],[New Rule Name]] -> VW_CUS0370_NationalSecurityIndicatorIsValid | AG20: ="create view "&Table362[[#This Row],[View Name]]&" ( "&IF(Table362[[#This Row],[Entity]]="Customer","KUNNR",IF(Table362[[#This Row],[Entity]]="Vendor","LIFNR","MATNR"))&", "&Table362[[#This Row],[Field]]&" ) as select "&IF(Table362[[#This Row],[Entity]]="Customer","KUNNR",IF(Table362[[#This Row],[Entity]]="Vendor","LIFNR","MATNR"))&", "&Table362[[#This Row],[Field]]&" from "&Table362[[#This Row],[Table]] -> create view VW_CUS0370_NationalSecurityIndicatorIsValid ( KUNNR, CCC03 ) as select KUNNR, CCC03 from KNA1 | AI20: expctrl | AK20: 37
A21: 17 | B21: IS_RDS | C21: Customer | D21: Finance | E21: Financial Accounting | F21: Customer Master (Company Code) | G21: CompanyCodeData | H21: AccountManagement | J21: =VLOOKUP(V21,Table_to_BRG!A:D,3,FALSE) -> Company Code data | K21: =VLOOKUP(V21,Table_to_BRG!A:D,2,FALSE) -> Company Code | P21: ZB_G14_CUST_InterestCycleIsValid | Q21: =UPPER(LEFT(Table362[[#This Row],[Entity]],3))&RIGHT("00"&Table362[[#This Row],[Rule '# by Entity]],3)&"0_"&MID(SUBSTITUTE(Table362[[#This Row],[Rule Name]],"_","|",3),SEARCH("|",SUBSTITUTE(Table362[[#This Row],[Rule Name]],"_","|",3))+1,LEN(Table362[[#This Row],[Rule Name]])) -> CUS0490_InterestCycleIsValid | R21: Verify the interest cycle value is valid according to the appropriate reference domain or value range. | S21: Accuracy | T21: Consistency | U21: $P_I_InterestCycle | V21: KNB1 | W21: ZINRT | X21: Interest calculation frequency in months | AA21: BEGIN RETURN $P_I_InterestCycle IN ('01', '02', '03', '04', '05', '06', '07', '08', '09', '10', '11', '12'); END | AB21: =Table362[[#This Row],[IS Parameter]]&" IS NOT NULL AND "& Table362[[#This Row],[IS Parameter]]&" != ''" -> $P_I_InterestCycle IS NOT NULL AND $P_I_InterestCycle != '' | AC21: QUAC.checkValueIsDomainFixedValue() | AE21: =IF(Table362[[#This Row],[Entity]]="Customer","KUNNR",IF(Table362[[#This Row],[Entity]]="Vendor","LIFNR","MATNR"))&",BUKRS"&","&Table362[[#This Row],[Field]] -> KUNNR,BUKRS,ZINRT | AF21: ="VW_"&Table362[[#This Row],[New Rule Name]] -> VW_CUS0490_InterestCycleIsValid | AG21: ="create view "&Table362[[#This Row],[View Name]]&" as select "&IF(Table362[[#This Row],[Entity]]="Customer","KUNNR",IF(Table362[[#This Row],[Entity]]="Vendor","LIFNR","MATNR"))&", BUKRS, "&Table362[[#This Row],[Field]]&" from "&Table362[[#This Row],[Table]] -> create view VW_CUS0490_InterestCycleIsValid as select KUNNR, BUKRS, ZINRT from KNB1 | AH21: Verify that interest calculation frequency is the same as interest cycle | AI21: intcycle01c | AK21: 49
